import doItAsync from './doItAsync.js';

const promise = doItAsync(true);
console.log(promise);

promise.then(
  (value) => {
    console.log('success: ', value);
  },
  (error) => {
    // geht auch, catch ist aber schÃ¶ner
    console.error('failure: ', error.message);
  },
);

promise.catch((e) => {
  console.error('failure im catch: ', e.message);
});

doItAsync()
  .then((value) => {
    console.log('1: ', value);
    return doItAsync();
  })
  .then((value) => {
    console.log('2: ', value);
    return doItAsync();
  })
  .then((value) => {
    console.log('3: ', value);
    return doItAsync();
  })
  .catch((error) => {
    console.error('OH NO: ', error);
  });
